Workbook

Sheet Invoice
X2: crt + h
J3: 52, RAJASWA COLONY,TANKI PATH FREEGANJ, UJJAIN MP | X3: Crt + u
J4: PH 0734-2530547,9425332517 | X4: crt + L
J5: SEED LIC NO- 1178
B6: नाम | G6: Name | K6: Invoice no | L6: =MAXIFS(Sale!B:B,Sale!A:A,A10)+1 -> 6
B7: ग्राम | G7: Village | K7: Date | L7: 13-09-2025
B8: मोबाईल | G8: Phone no | K8: GST EXEMPTED WHEAT SEED
B9: Sno | C9: Invoice no | D9: Customer name | E9: Village | F9: Mobile No | G9: remark | H9: Particular | I9: Bags | J9: Packing | K9: Quantity | L9: Rate | M9: Amount | N9: TOTAL BILL AMOUT | O9: Discoumt | P9: GRAND TOTAL | Q9: Advance | R9: Card Pay | S9: CASH TAKEN | T9: Difference | U9: Remark | V9: date | W9: BAG STOCK | X9: QTL STOCK
A10: =K$19 -> #N/A | B10: 1 | C10: =L$6 -> 6 | D10: =H$6 | E10: =H$7 | F10: =H$8 | G10: =L17 | J10: =if(H10>0,40,"") | K10: =IFERROR(I10*J10/100,"") -> 0 | L10: =iferror(VLOOKUP(H10,Table2[[Variety]:[RATE]],5,false),"") | M10: =iferror(L10*K10, "") -> 0 | N10: =M18 -> 0 | O10: =M19 | P10: =M20 -> 0 | Q10: =M21 | R10: =M22 | S10: =M23 -> 0 | T10: =M24 -> 0 | U10: =K18 -> VS | V10: =L$7 -> 13-09-2025 | W10: =VLOOKUP(H10,Table2[[Variety]:[In Stock]],4,false)-I10 -> #N/A | X10: =W10/0.4 -> #N/A
A11: =K$19 -> #N/A | B11: 2 | C11: =L$6 -> 6 | D11: =H$6 | E11: =H$7 | F11: =H$8 | J11: =if(H11>0,40,"") | K11: =IFERROR(I11*J11/100,"") -> 0 | L11: =iferror(VLOOKUP(H11,Table2[[Variety]:[RATE]],5,false),"") | M11: =iferror(L11*K11, "") -> 0 | V11: =L$7 -> 13-09-2025 | W11: =VLOOKUP(H11,Table2[[Variety]:[In Stock]],4,false)-I11 -> #N/A | X11: =W11/0.4 -> #N/A
A12: =K$19 -> #N/A | B12: 3 | C12: =L$6 -> 6 | D12: =H$6 | E12: =H$7 | F12: =H$8 | J12: =if(H12>0,40,"") | K12: =IFERROR(I12*J12/100,"") -> 0 | L12: =iferror(VLOOKUP(H12,Table2[[Variety]:[RATE]],5,false),"") | M12: =iferror(L12*K12, "") -> 0 | V12: =L$7 -> 13-09-2025 | W12: =VLOOKUP(H12,Table2[[Variety]:[In Stock]],4,false)-I12 -> #N/A | X12: =W12/0.4 -> #N/A
A13: =K$19 -> #N/A | B13: 4 | C13: =L$6 -> 6 | D13: =H$6 | E13: =H$7 | F13: =H$8 | J13: =if(H13>0,40,"") | K13: =IFERROR(I13*J13/100,"") -> 0 | L13: =iferror(VLOOKUP(H13,Table2[[Variety]:[RATE]],5,false),"") | M13: =iferror(L13*K13, "") -> 0 | V13: =L$7 -> 13-09-2025 | W13: =VLOOKUP(H13,Table2[[Variety]:[In Stock]],4,false)-I13 -> #N/A | X13: =W13/0.4 -> #N/A
A14: =K$19 -> #N/A | B14: 5 | C14: =L$6 -> 6 | D14: =H$6 | E14: =H$7 | F14: =H$8 | J14: =if(H14>0,40,"") | K14: =IFERROR(I14*J14/100,"") -> 0 | L14: =iferror(VLOOKUP(H14,Table2[[Variety]:[RATE]],5,false),"") | M14: =iferror(L14*K14, "") -> 0 | V14: =L$7 -> 13-09-2025 | W14: =VLOOKUP(H14,Table2[[Variety]:[In Stock]],4,false)-I14 -> #N/A | X14: =W14/0.4 -> #N/A
H15: . | I15: =sum(I10:I14) -> 0 | K15: =sum(K10:K14) -> 0 | L15: =sum(M10:M14) -> 0 | W15: Diff | X15: 0 | Y15: ="https://vasundharaseeds.in/pay.html?amount=" & sum(M10:M14) & "&invoice=" & MAXIFS(Sale!B:B,Sale!A:A,A10)+1 -> https://vasundharaseeds.in/pay.html?amount=0&invoice=6
H17: . | K17: Remark- | X17: =sum(Y18:Y24) -> 0
H18: . | K18: =IF(M36=0,IF(M34>0,"BANK-VS","VS"),"Credit-vs") -> VS | L18: Total | M18: =L15 -> 0 | Y18: =W18*X18 -> 0
H19: . | K19: =VLOOKUP(H10,Table2[],10,false) -> #N/A | Y19: =W19*X19 -> 0
H20: . | L20: Bill amount | M20: =M18-M19 -> 0 | Y20: =W20*X20 -> 0
H21: . | L21: Advance | Y21: =W21*X21 -> 0
H22: . | L22: Account Pay | Y22: =W22*X22 -> 0
H23: . | L23: Cash Taken | M23: =X17 -> 0 | Y23: =W23*X23 -> 0
H24: कृषक के हस्ताक्षर | J24: वास्ते वसुंधरा सीड्स | L24: Difference | M24: =M20-M21-M22-M23 -> 0 | Y24: =W24*X24 -> 0
C25: .
C26: .
C27: HI-8777 PUSA GEHU APR-2024-12-763-135627-FI-(I) | D27: VS | F27: I)
C28: GW-513 APR-2024-12-763-135624-FII-(I)-A | D28: VS | F28: -A
C29: GW-513 APR-2024-12-763-135624-FII-(I)-B | D29: VS | F29: -B
C30: GW-513 APR-2024-12-763-135624-FII-(II) | D30: VS | F30: I)
C31: HI-1544 (पूर्णा) APR-2024-12-763-135662-FI | D31: VS | F31: FI
C32: C-306 APR-2024-12-763-135670-FI | D32: VS | F32: FI
C33: HI-8830 (पूसा किर्ति) APR-2024-12-763-135635-FI-A | D33: VS | F33: -A
C34: HI-8830 (पूसा किर्ति) APR-2024-12-763-135635-FI-B | D34: VS | F34: -B
C35: HI-8663 (पोषण ) APR-2024-12-763-135628-FI-B | D35: VS | F35: -B
C36: LOK-1 APR-2024-12-763-135669-FI-A | D36: VS | F36: -A
C37: LOK-1 APR-2024-12-763-135668-FI-A | D37: VS | F37: -A
C38: LOK-1 APR-2024-12-763-135667-FI-A | D38: VS | F38: -A
... C52: HI-8830 (पूसा किर्ति) 40 KG | D52: TL | F52: KG
C53: GW-513 40 KG | D53: TL | F53: KG | H53: `
J55: 52, RAJASWA COLONY,TANKI PATH FREEGANJ, UJJAIN MP
J56: PH 0734-2530547,9425332517
...

Sheet Invoice2
J3: 52, RAJASWA COLONY,TANKI PATH FREEGANJ, UJJAIN MP
J4: PH 0734-2530547,9425332517 | X4: crt + L
J5: SEED LIC NO- 1178
B6: नाम | G6: Name | H6: DKSNDN | K6: Invoice no | L6: =MAXIFS(Sale!C:C,Sale!A:A,A10)+1 -> 2
B7: ग्राम | G7: Village | H7: DSDS | K7: Date | L7: 13-09-2025
B8: मोबाईल | G8: Phone no | H8: DSDS | K8: GST EXEMPTED WHEAT SEED
B9: Sno | C9: Invoice no | D9: Customer name | E9: Village | F9: Mobile No | G9: remark | H9: Particular | I9: Bags | J9: Packing | K9: Quantity | L9: Rate | M9: Amount | N9: TOTAL BILL AMOUT | O9: Discoumt | P9: GRAND TOTAL | Q9: Advance | R9: Card Pay | S9: CASH TAKEN | T9: Difference | U9: Remark | V9: date | W9: BAG STOCK | X9: QTL STOCK
A10: =K$19 -> #N/A | B10: 1 | C10: =L$6 -> 2 | D10: =H$6 -> DKSNDN | E10: =H$7 -> DSDS | F10: =H$8 -> DSDS | G10: =L17 | H10: HI-8759 ( पूसा तेजस) APR-2024-12-763-135644-FI | I10: 12 | J10: =if(H10>0,40,"") -> 40 | K10: =IFERROR(I10*J10/100,".") -> 4.8 | L10: =iferror(VLOOKUP(H10,Table2[[Variety]:[RATE]],5,false),"") | M10: =iferror(L10*K10, "") -> 0 | N10: =M18 -> 0 | O10: =M19 | P10: =M20 -> 0 | Q10: =M21 | R10: =M22 | S10: =M23 -> 0 | T10: =M24 -> 0 | U10: =K18 -> VS | V10: =L$7 -> 13-09-2025 | W10: =VLOOKUP(H10,Table2[[Variety]:[In Stock]],4,false)-I10 -> #N/A | X10: =W10/0.4 -> #N/A
A11: =K$19 -> #N/A | B11: 2 | C11: =L$6 -> 2 | D11: =H$6 -> DKSNDN | E11: =H$7 -> DSDS | F11: =H$8 -> DSDS | J11: =if(H11>0,40,"") | K11: =IFERROR(I11*J11/100,".") -> 0 | L11: =iferror(VLOOKUP(H11,Table2[[Variety]:[RATE]],5,false),"") | M11: =iferror(L11*K11, "") -> 0 | V11: =L$7 -> 13-09-2025 | W11: =VLOOKUP(H11,Table2[[Variety]:[In Stock]],4,false)-I11 -> #N/A | X11: =W11/0.4 -> #N/A
A12: =K$19 -> #N/A | B12: 3 | C12: =L$6 -> 2 | D12: =H$6 -> DKSNDN | E12: =H$7 -> DSDS | F12: =H$8 -> DSDS | J12: =if(H12>0,40,"") | K12: =IFERROR(I12*J12/100,"") -> 0 | L12: =iferror(VLOOKUP(H12,Table2[[Variety]:[RATE]],5,false),"") | M12: =iferror(L12*K12, "") -> 0 | V12: =L$7 -> 13-09-2025 | W12: =VLOOKUP(H12,Table2[[Variety]:[In Stock]],4,false)-I12 -> #N/A | X12: =W12/0.4 -> #N/A
A13: =K$19 -> #N/A | B13: 4 | C13: =L$6 -> 2 | D13: =H$6 -> DKSNDN | E13: =H$7 -> DSDS | F13: =H$8 -> DSDS | J13: =if(H13>0,40,"") | K13: =IFERROR(I13*J13/100,"") -> 0 | L13: =iferror(VLOOKUP(H13,Table2[[Variety]:[RATE]],5,false),"") | M13: =iferror(L13*K13, "") -> 0 | V13: =L$7 -> 13-09-2025 | W13: =VLOOKUP(H13,Table2[[Variety]:[In Stock]],4,false)-I13 -> #N/A | X13: =W13/0.4 -> #N/A
A14: =K$19 -> #N/A | B14: 5 | C14: =L$6 -> 2 | D14: =H$6 -> DKSNDN | E14: =H$7 -> DSDS | F14: =H$8 -> DSDS | J14: =if(H14>0,40,"") | K14: =IFERROR(I14*J14/100,"") -> 0 | L14: =iferror(VLOOKUP(H14,Table2[[Variety]:[RATE]],5,false),"") | M14: =iferror(L14*K14, "") -> 0 | V14: =L$7 -> 13-09-2025 | W14: =VLOOKUP(H14,Table2[[Variety]:[In Stock]],4,false)-I14 -> #N/A | X14: =W14/0.4 -> #N/A
H15: . | I15: =sum(I10:I14) -> 12 | K15: =sum(K10:K14) -> 4.8 | L15: =sum(M10:M14) -> 0 | W15: Diff | X15: 0
H17: . | K17: Remark- | X17: =sum(Y18:Y24) -> 0
H18: . | K18: =IF(M36=0,IF(M34>0,"BANK-VS","VS"),"Credit-vs") -> VS | L18: Total | M18: =L15 -> 0 | W18: 2000
H19: . | K19: =VLOOKUP(H10,Table2[],10,false) -> #N/A | W19: 500
H20: . | L20: Bill amount | M20: =M18-M19 -> 0 | W20: 200
H21: . | L21: Advance | W21: 100
H22: . | L22: Account Pay | W22: 50
H23: . | L23: Cash Taken | M23: =X17 -> 0 | W23: 20
H24: कृषक के हस्ताक्षर | J24: वास्ते वसुंधरा सीड्स | L24: Difference | M24: =M20-M21-M22-M23 -> 0 | W24: 10
C25: .
C26: .
C27: HI-8777 PUSA GEHU APR-2024-12-763-135627-FI-(I) | D27: VS | F27: I)
C28: GW-513 APR-2024-12-763-135624-FII-(I)-A | D28: VS | F28: -A
C29: GW-513 APR-2024-12-763-135624-FII-(I)-B | D29: VS | F29: -B
C30: GW-513 APR-2024-12-763-135624-FII-(II) | D30: VS | F30: I)
C31: HI-1544 (पूर्णा) APR-2024-12-763-135662-FI | D31: VS | F31: FI
C32: C-306 APR-2024-12-763-135670-FI | D32: VS | F32: FI
C33: HI-8830 (पूसा किर्ति) APR-2024-12-763-135635-FI-A | D33: VS | F33: -A
C34: HI-8830 (पूसा किर्ति) APR-2024-12-763-135635-FI-B | D34: VS | F34: -B
C35: HI-8663 (पोषण ) APR-2024-12-763-135628-FI-B | D35: VS | F35: -B
C36: LOK-1 APR-2024-12-763-135669-FI-A | D36: VS | F36: -A
C37: LOK-1 APR-2024-12-763-135668-FI-A | D37: VS | F37: -A
C38: LOK-1 APR-2024-12-763-135667-FI-A | D38: VS | F38: -A
... C52: HI-8830 (पूसा किर्ति) 40 KG | D52: TL | F52: KG
C53: GW-513 40 KG | D53: TL | F53: KG | H53: `
C54: HI-1650 ( पूसा ओजस्वी) APR-2024-12-763-135654-FI-A | D54: VS | F54: -A
C55: HI-1650 ( पूसा ओजस्वी) APR-2024-12-763-135654-FI-B | D55: VS | F55: -B
C56: HI-1636 ( पूसा वकुला) APR-2024-12-763-135660-FI | D56: VS | F56: FI
...

Sheet Sale
A1: Column1 | B1: Invoice no | C1: Customer name | D1: Village | E1: Mobile No | F1: remark | G1: Lot No | H1: Bags | I1: Weight | J1: Quantity | K1: Rate | L1: Amount | M1: TOTAL BILL AMOUT | N1: Discoumt | O1: GRAND TOTAL | P1: Card Pay | Q1: CASH TAKEN | R1: Difference | S1: Remark2 | T1: Date | U1: Remark2 | V1: Date
A2: TL | B2: 1 | C2: 8846 | H2: GW-513 40KG | I2: 5 | J2: 40 | K2: 2 | L2: 5300 | M2: 10600 | N2: 31800 | P2: 31800 | S2: 0 | T2: 31800 | U2: VS | V2: 13-09-2025 | W2: 1631 | X2: 4077.5
A3: TL | B3: 2 | C3: 8846 | H3: HI-1655(पूसा हर्षा) 40KG | I3: 10 | J3: 40 | K3: 4 | L3: 5300 | M3: 21200 | V3: 13-09-2025 | W3: 322 | X3: 805
A4: TL | B4: 3 | C4: 8846 | H4: JKG 5 KABULI 50KG | J4: 40 | K4: 0 | L4: 12000 | M4: 0 | V4: 13-09-2025 | W4: 60 | X4: 150
A5: TL | B5: 4 | C5: 8846 | K5: 0 | M5: 0 | V5: 13-09-2025 | W5: #N/A | X5: #N/A
A6: TL | B6: 5 | C6: 8846 | K6: 0 | M6: 0 | V6: 13-09-2025 | W6: #N/A | X6: #N/A
A7: #N/A | B7: 1 | C7: 1 | K7: 0 | M7: 0 | N7: 0 | P7: 0 | S7: 0 | T7: 0 | U7: VS | V7: 13-09-2025 | W7: #N/A | X7: #N/A
A8: #N/A | B8: 2 | C8: 1 | K8: 0 | M8: 0 | V8: 13-09-2025 | W8: #N/A | X8: #N/A
A9: #N/A | B9: 3 | C9: 1 | K9: 0 | M9: 0 | V9: 13-09-2025 | W9: #N/A | X9: #N/A
A10: #N/A | B10: 4 | C10: 1 | K10: 0 | M10: 0 | V10: 13-09-2025 | W10: #N/A | X10: #N/A
A11: #N/A | B11: 5 | C11: 1 | K11: 0 | M11: 0 | V11: 13-09-2025 | W11: #N/A | X11: #N/A
A12: TL | B12: 1 | C12: 8846 | D12: DINESH RAGHUWANSHI | E12: KAKARAYI | F12: 9977096885 | H12: GW-513 40KG | I12: 5 | J12: 40 | K12: 2 | L12: 5300 | M12: 10600 | N12: 10600 | P12: 10600 | S12: 0 | T12: 10600 | U12: VS | V12: 13-09-2025 | W12: 1636 | X12: 4090
A13: TL | B13: 2 | C13: 8846 | D13: DINESH RAGHUWANSHI | E13: KAKARAYI | F13: 9977096885 | K13: 0 | M13: 0 | V13: 13-09-2025 | W13: #N/A | X13: #N/A
A14: TL | B14: 3 | C14: 8846 | D14: DINESH RAGHUWANSHI | E14: KAKARAYI | F14: 9977096885 | K14: 0 | M14: 0 | V14: 13-09-2025 | W14: #N/A | X14: #N/A
A15: TL | B15: 4 | C15: 8846 | D15: DINESH RAGHUWANSHI | E15: KAKARAYI | F15: 9977096885 | K15: 0 | M15: 0 | V15: 13-09-2025 | W15: #N/A | X15: #N/A
A16: TL | B16: 5 | C16: 8846 | D16: DINESH RAGHUWANSHI | E16: KAKARAYI | F16: 9977096885 | K16: 0 | M16: 0 | V16: 13-09-2025 | W16: #N/A | X16: #N/A
A17: VS | B17: 19273 | C17: DINESH RAGHUWANSHI | D17: KAKARAYI | E17: 9977096885 | G17: HI-1650(पूसा ओजस्वी) MAR-25-12-763-40(3) (FII) | H17: 10 | I17: 40 | J17: 4 | K17: 5500 | L17: 22000 | M17: 26400 | N17: 2400 | O17: 24000 | Q17: 24000 | R17: 0 | S17: 0 | T17: VS | U17: 13-09-2025 | V17: 365 | W17: 912.5
A18: VS | B18: 19273 | C18: DINESH RAGHUWANSHI | D18: KAKARAYI | E18: 9977096885 | G18: GW-513 MAR-25-12-763-20(2) (CI) | H18: 2 | I18: 40 | J18: 0.8 | K18: 5500 | L18: 4400 | U18: 13-09-2025 | V18: 211 | W18: 527.5
A19: VS | B19: 19273 | C19: DINESH RAGHUWANSHI | D19: KAKARAYI | E19: 9977096885 | J19: 0 | L19: 0 | U19: 13-09-2025 | V19: #N/A | W19: #N/A
A20: VS | B20: 19273 | C20: DINESH RAGHUWANSHI | D20: KAKARAYI | E20: 9977096885 | J20: 0 | L20: 0 | U20: 13-09-2025 | V20: #N/A | W20: #N/A
A21: VS | B21: 19273 | C21: DINESH RAGHUWANSHI | D21: KAKARAYI | E21: 9977096885 | J21: 0 | L21: 0 | U21: 13-09-2025 | V21: #N/A | W21: #N/A
A22: TL | B22: 8845 | C22: RAJPAL SINGH | D22: KACHNARIYA | E22: 9425915634 | F22: 0 | G22: 33-86 50KG | H22: 2 | I22: 50 | J22: 1 | K22: 5000 | L22: 5000 | M22: 5000 | N22: 500 | O22: 4500 | P22: 4500 | Q22: 0 | R22: 0 | S22: BANK-VS | T22: 21-11-2025
A23: TL | B23: 8845 | C23: RAJPAL SINGH | D23: KACHNARIYA | E23: 9425915634 | T23: 21-11-2025
A24: TL | B24: 8845 | C24: RAJPAL SINGH | D24: KACHNARIYA | E24: 9425915634 | T24: 21-11-2025
A25: TL | B25: 8845 | C25: RAJPAL SINGH | D25: KACHNARIYA | E25: 9425915634 | T25: 21-11-2025
A26: TL | B26: 8845 | C26: RAJPAL SINGH | D26: KACHNARIYA | E26: 9425915634 | T26: 21-11-2025
A27: TL | B27: 8844 | C27: RAJESH VISHWAKARMA | D27: NIMBODA | E27: 9893274817 | F27: 0 | G27: HI-8830(पूसा किर्ति) 40KG | H27: 3 | I27: 40 | J27: 1.2 | K27: 5300 | L27: 6360 | M27: 6360 | N27: 0 | O27: 6360 | P27: 6360 | Q27: 0 | R27: 0 | S27: BANK-VS | T27: 21-11-2025
A28: TL | B28: 8844 | C28: RAJESH VISHWAKARMA | D28: NIMBODA | E28: 9893274817 | T28: 21-11-2025
A29: TL | B29: 8844 | C29: RAJESH VISHWAKARMA | D29: NIMBODA | E29: 9893274817 | T29: 21-11-2025
A30: TL | B30: 8844 | C30: RAJESH VISHWAKARMA | D30: NIMBODA | E30: 9893274817 | T30: 21-11-2025
A31: TL | B31: 8844 | C31: RAJESH VISHWAKARMA | D31: NIMBODA | E31: 9893274817 | T31: 21-11-2025
A32: TL | B32: 8843 | C32: AMAN SHARMA | D32: SUTLI | E32: 8643030828 | F32: 0 | G32: HI-1650(पूसा ओजस्वी) 40KG | H32: 1 | I32: 40 | J32: 0.4 | K32: 5300 | L32: 2120 | M32: 2120 | N32: 120 | O32: 2000 | P32: 0 | Q32: 2000 | R32: 0 | S32: VS | T32: 21-11-2025
A33: TL | B33: 8843 | C33: AMAN SHARMA | D33: SUTLI | E33: 8643030828 | T33: 21-11-2025
A34: TL | B34: 8843 | C34: AMAN SHARMA | D34: SUTLI | E34: 8643030828 | T34: 21-11-2025
A35: TL | B35: 8843 | C35: AMAN SHARMA | D35: SUTLI | E35: 8643030828 | T35: 21-11-2025
A36: TL | B36: 8843 | C36: AMAN SHARMA | D36: SUTLI | E36: 8643030828 | T36: 21-11-2025
A37: TL | B37: 8842 | C37: KAMALS SINGH | D37: LABAYCHYA | E37: 9907257138 | F37: 0 | G37: HI-8830(पूसा किर्ति) 40KG | H37: 3 | I37: 40 | J37: 1.2 | K37: 5300 | L37: 6360 | M37: 6360 | N37: 560 | O37: 5800 | P37: 0 | Q37: 5800 | R37: 0 | S37: VS | T37: 21-11-2025
A38: TL | B38: 8842 | C38: KAMALS SINGH | D38: LABAYCHYA | E38: 9907257138 | T38: 21-11-2025
A39: TL | B39: 8842 | C39: KAMALS SINGH | D39: LABAYCHYA | E39: 9907257138 | T39: 21-11-2025
A40: TL | B40: 8842 | C40: KAMALS SINGH | D40: LABAYCHYA | E40: 9907257138 | T40: 21-11-2025
...

Sheet Purchase
B4: Date | C4: Column3 | D4: Lot No | E4: Variety | F4: Bags | G4: Weight | H4: Quantity | I4: Column1 | J4: Column2 | K4: RATE
B5: 45912 | C5: GW-513 | D5: MAR-25-12-763-20 (CI) | E5: GW-513 MAR-25-12-763-20 (CI) | F5: 300 | G5: 40 | H5: 120 | I5: 5500 | K5: MP
B6: 45912 | C6: GW-513 | D6: MAR-25-12-763-20(2) (CI) | E6: GW-513 MAR-25-12-763-20(2) (CI) | F6: 163 | G6: 40 | H6: 65.2 | I6: 5500 | K6: MP
B7: 45912 | C7: GW-513 | D7: MAR-25-12-763-20 (CI) | E7: GW-513 MAR-25-12-763-20 (CI) | F7: 145 | G7: 40 | H7: 58 | I7: 5500 | K7: MP
B8: 45912 | C8: GW-322 | D8: MAR-25-12-763-49 (CI) | E8: GW-322 MAR-25-12-763-49 (CI) | F8: 300 | G8: 40 | H8: 120 | I8: 5500 | K8: GD
B9: 45912 | C9: GW-322 | D9: MAR-25-12-763-50 (CI) | E9: GW-322 MAR-25-12-763-50 (CI) | F9: 162 | G9: 40 | H9: 64.8 | I9: 5500 | K9: GD
B10: 45913 | C10: GW-322 | D10: MAR-25-12-763-49 (CI) | E10: GW-322 MAR-25-12-763-49 (CI) | F10: 138 | G10: 40 | H10: 55.2 | I10: 5500 | K10: GD
B11: 45913 | C11: GW-322 | D11: MAR-25-12-763-50 (CI) | E11: GW-322 MAR-25-12-763-50 (CI) | F11: 197 | G11: 40 | H11: 78.8 | I11: 5500 | K11: GD
B12: 45913 | C12: GW-513 | D12: 40KG | E12: GW-513 40KG | F12: 65 | G12: 40 | H12: 26 | I12: 5300 | K12: MP
B13: 45915 | C13: HD-4728(पूसा मालवी) | D13: MAR-25-12-763-38 (CI) | E13: HD-4728(पूसा मालवी) MAR-25-12-763-38 (CI) | F13: 300 | G13: 40 | H13: 120 | I13: 5500 | K13: SB
B14: 45915 | C14: HD-4728(पूसा मालवी) | D14: MAR-25-12-763-38 (CI) | E14: HD-4728(पूसा मालवी) MAR-25-12-763-38 (CI) | F14: 142 | G14: 40 | H14: 56.8 | I14: 5500 | K14: SB
B15: 45915 | C15: HD-4728(पूसा मालवी) | D15: MAR-25-12-763-37 (CI) | E15: HD-4728(पूसा मालवी) MAR-25-12-763-37 (CI) | F15: 82 | G15: 40 | H15: 32.8 | I15: 5500 | K15: SB
B16: 45915 | C16: GW-322 | D16: 40KG | E16: GW-322 40KG | F16: 76 | G16: 40 | H16: 30.4 | I16: 5300 | K16: GD
... B39: 45925 | C39: HI-8713(पूसा मंगल) | D39: MAR-25-12-763-36(2) (FII) | E39: HI-8713(पूसा मंगल) MAR-25-12-763-36(2) (FII) | F39: 97 | G39: 40 | H39: 38.8 | I39: 5500 | K39: JA
B40: 45927 | C40: 8826 | D40: 40KG | E40: 8826 40KG | F40: 209 | G40: 40 | H40: 83.6 | I40: 5000 | K40: GL
B41: 45927 | C41: 8826 | D41: 40KG | E41: 8826 40KG | F41: 99 | G41: 40 | H41: 39.6 | I41: 5000 | K41: RB
B42: 45927 | C42: HI-1655(पूसा हर्षा) | D42: 40KG | E42: HI-1655(पूसा हर्षा) 40KG | F42: 332 | G42: 40 | H42: 132.8 | I42: 5300 | K42: MIX
B43: 45927 | C43: HI-1655(पूसा हर्षा) | D43: MAR-25-12-763-21 (FI) | E43: HI-1655(पूसा हर्षा) MAR-25-12-763-21 (FI) | F43: 110 | G43: 40 | H43: 44 | I43: 5500 | K43: VS
B44: 45927 | C44: 8826 | D44: 40KG | E44: 8826 40KG | F44: 46 | G44: 40 | H44: 18.4 | I44: 5000 | K44: GL
B45: 45927 | C45: HI-1650(पूसा ओजस्वी) | D45: 40KG | E45: HI-1650(पूसा ओजस्वी) 40KG | F45: 149 | G45: 40 | H45: 59.6 | I45: 5300 | K45: 0
C46: HI-1634(पूसा अहिल्या) | D46: 40KG | E46: HI-1634(पूसा अहिल्या) 40KG | F46: 1222 | G46: 40 | H46: 488.8 | I46: 5300 | K46: IS
C47: HD-3385 | D47: 40KG | E47: HD-3385 40KG | F47: 863 | G47: 40 | H47: 345.2 | I47: 5300 | K47: AS
C48: HD-3385 | D48: 40KG | E48: HD-3385 40KG | F48: 376 | G48: 40 | H48: 150.4 | I48: 5300 | K48: BA
C49: HD-3385 | D49: 40KG | E49: HD-3385 40KG | F49: 1093 | G49: 40 | H49: 437.2 | I49: 5300 | K49: HR
C50: HD-3385 | D50: 40KG | E50: HD-3385 40KG | F50: 183 | G50: 40 | H50: 73.2 | I50: 5300 | K50: KR
C51: HD-3385 | D51: 40KG | E51: HD-3385 40KG | F51: 341 | G51: 40 | H51: 136.4 | I51: 5300 | K51: MS
C52: HD-3385 | D52: 40KG | E52: HD-3385 40KG | F52: 1240 | G52: 40 | H52: 496 | I52: 5300 | K52: RN
C53: HD-3385 | D53: 40KG | E53: HD-3385 40KG | F53: 1269 | G53: 40 | H53: 507.6 | I53: 5300 | K53: RS
C54: HD-3385 | D54: 40KG | E54: HD-3385 40KG | F54: 66 | G54: 40 | H54: 26.4 | I54: 5300 | K54: RR
C55: 33-88 40KG | E55: 33-88 40KG | F55: 230 | G55: 40 | H55: 92 | I55: 5000 | K55: DD
C56: 3390 40KG | E56: 3390 40KG | F56: 154 | G56: 40 | H56: 61.6 | I56: 5000 | K56: RR
C57: 3390 40KG | E57: 3390 40KG | F57: 410 | G57: 40 | H57: 164 | I57: 5000 | K57: SN
C58: HD-3410 | D58: 40KG | E58: HD-3410 40KG | F58: 272 | G58: 40 | H58: 108.8 | I58: 5300 | K58: DP
C59: HD-3410 | D59: 40KG | E59: HD-3410 40KG | F59: 137 | G59: 40 | H59: 54.8 | I59: 5300 | K59: JD
C60: HD-3410 | D60: 40KG | E60: HD-3410 40KG | F60: 26 | G60: 40 | H60: 10.4 | I60: 5300 | K60: RR
C61: HD-3410 | D61: 40KG | E61: HD-3410 40KG | F61: 349 | G61: 40 | H61: 139.6 | I61: 5300 | K61: SN
C62: HI-8830(पूसा किर्ति) | D62: 40KG | E62: HI-8830(पूसा किर्ति) 40KG | F62: 482 | G62: 40 | H62: 192.8 | I62: 5300 | K62: DS
C63: HI-8830(पूसा किर्ति) | D63: 40KG | E63: HI-8830(पूसा किर्ति) 40KG | F63: 1073 | G63: 40 | H63: 429.2 | I63: 5300 | K63: KB
C64: HI-8830(पूसा किर्ति) | D64: 40KG | E64: HI-8830(पूसा किर्ति) 40KG | F64: 673 | G64: 40 | H64: 269.2 | I64: 5300 | K64: 3
C65: HI-8830(पूसा किर्ति) | D65: 40KG | E65: HI-8830(पूसा किर्ति) 40KG | F65: 358 | G65: 40 | H65: 143.2 | I65: 5300 | K65: RB
...

Sheet Inventory
B2: Variety | C2: Purchse Qty | D2: Sale Qty | E2: In Stock | F2: RATE | G2: Purchse Qty2 | H2: Sale Qty3 | I2: In Stock4 | J2: HOLD | K2: Column 1
B3: {=UNIQUE(Purchase!E5:E334)} -> GW-513 MAR-25-12-763-20 (CI) | C3: =sumif(Purchase!E$5:E1000,B3,Purchase!F$5:F1000) -> 445 | D3: =SUMIF(Sale!H:H,B3,Sale!I:I) -> 0 | E3: =C3-D3 -> 445 | F3: =VLOOKUP(B3,Table1[[Variety]:[Column1]],5,FALSE) -> 5500 | G3: =C3*0.4 -> 178 | H3: =D3*0.4 -> 0 | I3: =E3*0.4 -> 178 | K3: =IF(right(B3,2)="KG","TL","VS") -> VS
B4: GW-513 MAR-25-12-763-20(2) (CI) | C4: =sumif(Purchase!E$5:E1000,B4,Purchase!F$5:F1000) -> 213 | D4: =SUMIF(Sale!H:H,B4,Sale!I:I) -> 0 | E4: =C4-D4 -> 213 | F4: =VLOOKUP(B4,Table1[[Variety]:[Column1]],5,FALSE) -> 5500 | G4: =C4*0.4 -> 85.2 | H4: =D4*0.4 -> 0 | I4: =E4*0.4 -> 85.2 | K4: =IF(right(B4,2)="KG","TL","VS") -> VS
B5: GW-322 MAR-25-12-763-49 (CI) | C5: =sumif(Purchase!E$5:E1000,B5,Purchase!F$5:F1000) -> 438 | D5: =SUMIF(Sale!H:H,B5,Sale!I:I) -> 0 | E5: =C5-D5 -> 438 | F5: =VLOOKUP(B5,Table1[[Variety]:[Column1]],5,FALSE) -> 5500 | G5: =C5*0.4 -> 175.2 | H5: =D5*0.4 -> 0 | I5: =E5*0.4 -> 175.2 | K5: =IF(right(B5,2)="KG","TL","VS") -> VS
B6: GW-322 MAR-25-12-763-50 (CI) | C6: =sumif(Purchase!E$5:E1000,B6,Purchase!F$5:F1000) -> 409 | D6: =SUMIF(Sale!H:H,B6,Sale!I:I) -> 0 | E6: =C6-D6 -> 409 | F6: =VLOOKUP(B6,Table1[[Variety]:[Column1]],5,FALSE) -> 5500 | G6: =C6*0.4 -> 163.6 | H6: =D6*0.4 -> 0 | I6: =E6*0.4 -> 163.6 | K6: =IF(right(B6,2)="KG","TL","VS") -> VS
B7: GW-513 40KG | C7: =sumif(Purchase!E$5:E1000,B7,Purchase!F$5:F1000) -> 1641 | D7: =SUMIF(Sale!H:H,B7,Sale!I:I) -> 10 | E7: =C7-D7 -> 1631 | F7: =VLOOKUP(B7,Table1[[Variety]:[Column1]],5,FALSE) -> 5300 | G7: =C7*0.4 -> 656.4 | H7: =D7*0.4 -> 4 | I7: =E7*0.4 -> 652.4 | K7: =IF(right(B7,2)="KG","TL","VS") -> TL
B8: HD-4728(पूसा मालवी) MAR-25-12-763-38 (CI) | C8: =sumif(Purchase!E$5:E1000,B8,Purchase!F$5:F1000) -> 442 | D8: =SUMIF(Sale!H:H,B8,Sale!I:I) -> 0 | E8: =C8-D8 -> 442 | F8: =VLOOKUP(B8,Table1[[Variety]:[Column1]],5,FALSE) -> 5500 | G8: =C8*0.4 -> 176.8 | H8: =D8*0.4 -> 0 | I8: =E8*0.4 -> 176.8 | K8: =IF(right(B8,2)="KG","TL","VS") -> VS
B9: HD-4728(पूसा मालवी) MAR-25-12-763-37 (CI) | C9: =sumif(Purchase!E$5:E1000,B9,Purchase!F$5:F1000) -> 132 | D9: =SUMIF(Sale!H:H,B9,Sale!I:I) -> 0 | E9: =C9-D9 -> 132 | F9: =VLOOKUP(B9,Table1[[Variety]:[Column1]],5,FALSE) -> 5500 | G9: =C9*0.4 -> 52.8 | H9: =D9*0.4 -> 0 | I9: =E9*0.4 -> 52.8 | K9: =IF(right(B9,2)="KG","TL","VS") -> VS
B10: GW-322 40KG | C10: =sumif(Purchase!E$5:E1000,B10,Purchase!F$5:F1000) -> 76 | D10: =SUMIF(Sale!H:H,B10,Sale!I:I) -> 0 | E10: =C10-D10 -> 76 | F10: =VLOOKUP(B10,Table1[[Variety]:[Column1]],5,FALSE) -> 5300 | G10: =C10*0.4 -> 30.4 | H10: =D10*0.4 -> 0 | I10: =E10*0.4 -> 30.4 | K10: =IF(right(B10,2)="KG","TL","VS") -> TL
B11: LOK-1 MAR-25-12-763-13 (FI) | C11: =sumif(Purchase!E$5:E1000,B11,Purchase!F$5:F1000) -> 430 | D11: =SUMIF(Sale!H:H,B11,Sale!I:I) -> 0 | E11: =C11-D11 -> 430 | F11: =VLOOKUP(B11,Table1[[Variety]:[Column1]],5,FALSE) -> 5500 | G11: =C11*0.4 -> 172 | H11: =D11*0.4 -> 0 | I11: =E11*0.4 -> 172 | K11: =IF(right(B11,2)="KG","TL","VS") -> VS
B12: LOK-1 MAR-25-12-763-14 (FI) | C12: =sumif(Purchase!E$5:E1000,B12,Purchase!F$5:F1000) -> 171 | D12: =SUMIF(Sale!H:H,B12,Sale!I:I) -> 0 | E12: =C12-D12 -> 171 | F12: =VLOOKUP(B12,Table1[[Variety]:[Column1]],5,FALSE) -> 5500 | G12: =C12*0.4 -> 68.4 | H12: =D12*0.4 -> 0 | I12: =E12*0.4 -> 68.4 | K12: =IF(right(B12,2)="KG","TL","VS") -> VS
B13: LOK-1 MAR-25-12-763-19 (FI) | C13: =sumif(Purchase!E$5:E1000,B13,Purchase!F$5:F1000) -> 446 | D13: =SUMIF(Sale!H:H,B13,Sale!I:I) -> 0 | E13: =C13-D13 -> 446 | F13: =VLOOKUP(B13,Table1[[Variety]:[Column1]],5,FALSE) -> 5500 | G13: =C13*0.4 -> 178.4 | H13: =D13*0.4 -> 0 | I13: =E13*0.4 -> 178.4 | K13: =IF(right(B13,2)="KG","TL","VS") -> VS
B14: LOK-1 MAR-25-12-763-12 (FI) | C14: =sumif(Purchase!E$5:E1000,B14,Purchase!F$5:F1000) -> 200 | D14: =SUMIF(Sale!H:H,B14,Sale!I:I) -> 0 | E14: =C14-D14 -> 200 | F14: =VLOOKUP(B14,Table1[[Variety]:[Column1]],5,FALSE) -> 5500 | G14: =C14*0.4 -> 80 | H14: =D14*0.4 -> 0 | I14: =E14*0.4 -> 80 | K14: =IF(right(B14,2)="KG","TL","VS") -> VS
B15: HI-1650(पूसा ओजस्वी) MAR-25-12-763-40(3) (FII) | C15: =sumif(Purchase!E$5:E1000,B15,Purchase!F$5:F1000) -> 375 | D15: =SUMIF(Sale!H:H,B15,Sale!I:I) -> 0 | E15: =C15-D15 -> 375 | F15: =VLOOKUP(B15,Table1[[Variety]:[Column1]],5,FALSE) -> 5500 | G15: =C15*0.4 -> 150 | H15: =D15*0.4 -> 0 | I15: =E15*0.4 -> 150 | K15: =IF(right(B15,2)="KG","TL","VS") -> VS
B16: HI-1650(पूसा ओजस्वी) MAR-25-12-763-40 (FII) | C16: =sumif(Purchase!E$5:E1000,B16,Purchase!F$5:F1000) -> 342 | D16: =SUMIF(Sale!H:H,B16,Sale!I:I) -> 0 | E16: =C16-D16 -> 342 | F16: =VLOOKUP(B16,Table1[[Variety]:[Column1]],5,FALSE) -> 5500 | G16: =C16*0.4 -> 136.8 | H16: =D16*0.4 -> 0 | I16: =E16*0.4 -> 136.8 | K16: =IF(right(B16,2)="KG","TL","VS") -> VS
B17: HI-1650(पूसा ओजस्वी) MAR-25-12-763-40(2) (FII) | C17: =sumif(Purchase!E$5:E1000,B17,Purchase!F$5:F1000) -> 338 | D17: =SUMIF(Sale!H:H,B17,Sale!I:I) -> 0 | E17: =C17-D17 -> 338 | F17: =VLOOKUP(B17,Table1[[Variety]:[Column1]],5,FALSE) -> 5500 | G17: =C17*0.4 -> 135.2 | H17: =D17*0.4 -> 0 | I17: =E17*0.4 -> 135.2 | K17: =IF(right(B17,2)="KG","TL","VS") -> VS
B18: C-306 MAR-25-12-763-1 (FII) | C18: =sumif(Purchase!E$5:E1000,B18,Purchase!F$5:F1000) -> 340 | D18: =SUMIF(Sale!H:H,B18,Sale!I:I) -> 0 | E18: =C18-D18 -> 340 | F18: =VLOOKUP(B18,Table1[[Variety]:[Column1]],5,FALSE) -> 6500 | G18: =C18*0.4 -> 136 | H18: =D18*0.4 -> 0 | I18: =E18*0.4 -> 136 | K18: =IF(right(B18,2)="KG","TL","VS") -> VS
B19: C-306 40KG | C19: =sumif(Purchase!E$5:E1000,B19,Purchase!F$5:F1000) -> 877 | D19: =SUMIF(Sale!H:H,B19,Sale!I:I) -> 0 | E19: =C19-D19 -> 877 | F19: =VLOOKUP(B19,Table1[[Variety]:[Column1]],5,FALSE) -> 6000 | G19: =C19*0.4 -> 350.8 | H19: =D19*0.4 -> 0 | I19: =E19*0.4 -> 350.8 | K19: =IF(right(B19,2)="KG","TL","VS") -> TL
B20: HI-8713(पूसा मंगल) MAR-25-12-763-35 (FII) | C20: =sumif(Purchase!E$5:E1000,B20,Purchase!F$5:F1000) -> 433 | D20: =SUMIF(Sale!H:H,B20,Sale!I:I) -> 0 | E20: =C20-D20 -> 433 | F20: =VLOOKUP(B20,Table1[[Variety]:[Column1]],5,FALSE) -> 5500 | G20: =C20*0.4 -> 173.2 | H20: =D20*0.4 -> 0 | I20: =E20*0.4 -> 173.2 | K20: =IF(right(B20,2)="KG","TL","VS") -> VS
B21: HI-8713(पूसा मंगल) MAR-25-12-763-36(2) (FII) | C21: =sumif(Purchase!E$5:E1000,B21,Purchase!F$5:F1000) -> 212 | D21: =SUMIF(Sale!H:H,B21,Sale!I:I) -> 0 | E21: =C21-D21 -> 212 | F21: =VLOOKUP(B21,Table1[[Variety]:[Column1]],5,FALSE) -> 5500 | G21: =C21*0.4 -> 84.8 | H21: =D21*0.4 -> 0 | I21: =E21*0.4 -> 84.8 | K21: =IF(right(B21,2)="KG","TL","VS") -> VS
B22: 8826 40KG | C22: =sumif(Purchase!E$5:E1000,B22,Purchase!F$5:F1000) -> 354 | D22: =SUMIF(Sale!H:H,B22,Sale!I:I) -> 0 | E22: =C22-D22 -> 354 | F22: =VLOOKUP(B22,Table1[[Variety]:[Column1]],5,FALSE) -> 5000 | G22: =C22*0.4 -> 141.6 | H22: =D22*0.4 -> 0 | I22: =E22*0.4 -> 141.6 | K22: =IF(right(B22,2)="KG","TL","VS") -> TL
B23: HI-1655(पूसा हर्षा) 40KG | C23: =sumif(Purchase!E$5:E1000,B23,Purchase!F$5:F1000) -> 332 | D23: =SUMIF(Sale!H:H,B23,Sale!I:I) -> 10 | E23: =C23-D23 -> 322 | F23: =VLOOKUP(B23,Table1[[Variety]:[Column1]],5,FALSE) -> 5300 | G23: =C23*0.4 -> 132.8 | H23: =D23*0.4 -> 4 | I23: =E23*0.4 -> 128.8 | K23: =IF(right(B23,2)="KG","TL","VS") -> TL
B24: HI-1655(पूसा हर्षा) MAR-25-12-763-21 (FI) | C24: =sumif(Purchase!E$5:E1000,B24,Purchase!F$5:F1000) -> 130 | D24: =SUMIF(Sale!H:H,B24,Sale!I:I) -> 0 | E24: =C24-D24 -> 130 | F24: =VLOOKUP(B24,Table1[[Variety]:[Column1]],5,FALSE) -> 5500 | G24: =C24*0.4 -> 52 | H24: =D24*0.4 -> 0 | I24: =E24*0.4 -> 52 | K24: =IF(right(B24,2)="KG","TL","VS") -> VS
B25: HI-1650(पूसा ओजस्वी) 40KG | C25: =sumif(Purchase!E$5:E1000,B25,Purchase!F$5:F1000) -> 3891 | D25: =SUMIF(Sale!H:H,B25,Sale!I:I) -> 0 | E25: =C25-D25 -> 3891 | F25: =VLOOKUP(B25,Table1[[Variety]:[Column1]],5,FALSE) -> 5300 | G25: =C25*0.4 -> 1556.4 | H25: =D25*0.4 -> 0 | I25: =E25*0.4 -> 1556.4 | K25: =IF(right(B25,2)="KG","TL","VS") -> TL
B26: HI-1634(पूसा अहिल्या) 40KG | C26: =sumif(Purchase!E$5:E1000,B26,Purchase!F$5:F1000) -> 1272 | D26: =SUMIF(Sale!H:H,B26,Sale!I:I) -> 0 | E26: =C26-D26 -> 1272 | F26: =VLOOKUP(B26,Table1[[Variety]:[Column1]],5,FALSE) -> 5300 | G26: =C26*0.4 -> 508.8 | H26: =D26*0.4 -> 0 | I26: =E26*0.4 -> 508.8 | K26: =IF(right(B26,2)="KG","TL","VS") -> TL
B27: HD-3385 40KG | C27: =sumif(Purchase!E$5:E1000,B27,Purchase!F$5:F1000) -> 5431 | D27: =SUMIF(Sale!H:H,B27,Sale!I:I) -> 0 | E27: =C27-D27 -> 5431 | F27: =VLOOKUP(B27,Table1[[Variety]:[Column1]],5,FALSE) -> 5300 | G27: =C27*0.4 -> 2172.4 | H27: =D27*0.4 -> 0 | I27: =E27*0.4 -> 2172.4 | K27: =IF(right(B27,2)="KG","TL","VS") -> TL
B28: 33-88 40KG | C28: =sumif(Purchase!E$5:E1000,B28,Purchase!F$5:F1000) -> 259 | D28: =SUMIF(Sale!H:H,B28,Sale!I:I) -> 0 | E28: =C28-D28 -> 259 | F28: =VLOOKUP(B28,Table1[[Variety]:[Column1]],5,FALSE) -> 5000 | G28: =C28*0.4 -> 103.6 | H28: =D28*0.4 -> 0 | I28: =E28*0.4 -> 103.6 | K28: =IF(right(B28,2)="KG","TL","VS") -> TL
B29: 3390 40KG | C29: =sumif(Purchase!E$5:E1000,B29,Purchase!F$5:F1000) -> 564 | D29: =SUMIF(Sale!H:H,B29,Sale!I:I) -> 0 | E29: =C29-D29 -> 564 | F29: =VLOOKUP(B29,Table1[[Variety]:[Column1]],5,FALSE) -> 5000 | G29: =C29*0.4 -> 225.6 | H29: =D29*0.4 -> 0 | I29: =E29*0.4 -> 225.6 | K29: =IF(right(B29,2)="KG","TL","VS") -> TL
B30: HD-3410 40KG | C30: =sumif(Purchase!E$5:E1000,B30,Purchase!F$5:F1000) -> 784 | D30: =SUMIF(Sale!H:H,B30,Sale!I:I) -> 0 | E30: =C30-D30 -> 784 | F30: =VLOOKUP(B30,Table1[[Variety]:[Column1]],5,FALSE) -> 5300 | G30: =C30*0.4 -> 313.6 | H30: =D30*0.4 -> 0 | I30: =E30*0.4 -> 313.6 | K30: =IF(right(B30,2)="KG","TL","VS") -> TL
B31: HI-8830(पूसा किर्ति) 40KG | C31: =sumif(Purchase!E$5:E1000,B31,Purchase!F$5:F1000) -> 8257 | D31: =SUMIF(Sale!H:H,B31,Sale!I:I) -> 0 | E31: =C31-D31 -> 8257 | F31: =VLOOKUP(B31,Table1[[Variety]:[Column1]],5,FALSE) -> 5300 | G31: =C31*0.4 -> 3302.8 | H31: =D31*0.4 -> 0 | I31: =E31*0.4 -> 3302.8 | K31: =IF(right(B31,2)="KG","TL","VS") -> TL
B32: HD-3385 BR 40KG | C32: =sumif(Purchase!E$5:E1000,B32,Purchase!F$5:F1000) -> 259 | D32: =SUMIF(Sale!H:H,B32,Sale!I:I) -> 0 | E32: =C32-D32 -> 259 | F32: =VLOOKUP(B32,Table1[[Variety]:[Column1]],5,FALSE) -> 7000 | G32: =C32*0.4 -> 103.6 | H32: =D32*0.4 -> 0 | I32: =E32*0.4 -> 103.6 | K32: =IF(right(B32,2)="KG","TL","VS") -> TL
B33: LOK-1 40KG | C33: =sumif(Purchase!E$5:E1000,B33,Purchase!F$5:F1000) -> 688 | D33: =SUMIF(Sale!H:H,B33,Sale!I:I) -> 0 | E33: =C33-D33 -> 688 | F33: =VLOOKUP(B33,Table1[[Variety]:[Column1]],5,FALSE) -> 5300 | G33: =C33*0.4 -> 275.2 | H33: =D33*0.4 -> 0 | I33: =E33*0.4 -> 275.2 | K33: =IF(right(B33,2)="KG","TL","VS") -> TL
B34: PRADHAN(प्रधान) 40KG | C34: =sumif(Purchase!E$5:E1000,B34,Purchase!F$5:F1000) -> 945 | D34: =SUMIF(Sale!H:H,B34,Sale!I:I) -> 0 | E34: =C34-D34 -> 945 | F34: =VLOOKUP(B34,Table1[[Variety]:[Column1]],5,FALSE) -> 5000 | G34: =C34*0.4 -> 378 | H34: =D34*0.4 -> 0 | I34: =E34*0.4 -> 378 | K34: =IF(right(B34,2)="KG","TL","VS") -> TL
B35: MANAV(मानव) 40KG | C35: =sumif(Purchase!E$5:E1000,B35,Purchase!F$5:F1000) -> 199 | D35: =SUMIF(Sale!H:H,B35,Sale!I:I) -> 0 | E35: =C35-D35 -> 199 | F35: =VLOOKUP(B35,Table1[[Variety]:[Column1]],5,FALSE) -> 12000 | G35: =C35*0.4 -> 79.6 | H35: =D35*0.4 -> 0 | I35: =E35*0.4 -> 79.6 | K35: =IF(right(B35,2)="KG","TL","VS") -> TL
B36: SAMRUDDHI(समृद्धि) 40KG | C36: =sumif(Purchase!E$5:E1000,B36,Purchase!F$5:F1000) -> 127 | D36: =SUMIF(Sale!H:H,B36,Sale!I:I) -> 0 | E36: =C36-D36 -> 127 | F36: =VLOOKUP(B36,Table1[[Variety]:[Column1]],5,FALSE) -> 8000 | G36: =C36*0.4 -> 50.8 | H36: =D36*0.4 -> 0 | I36: =E36*0.4 -> 50.8 | K36: =IF(right(B36,2)="KG","TL","VS") -> TL
B37: HI-8759(पूसा तेजस) 40KG | C37: =sumif(Purchase!E$5:E1000,B37,Purchase!F$5:F1000) -> 8615 | D37: =SUMIF(Sale!H:H,B37,Sale!I:I) -> 0 | E37: =C37-D37 -> 8615 | F37: =VLOOKUP(B37,Table1[[Variety]:[Column1]],5,FALSE) -> 5300 | G37: =C37*0.4 -> 3446 | H37: =D37*0.4 -> 0 | I37: =E37*0.4 -> 3446 | K37: =IF(right(B37,2)="KG","TL","VS") -> TL
B38: HI-8713(पूसा मंगल) MAR-25-12-763-36 (FII) | C38: =sumif(Purchase!E$5:E1000,B38,Purchase!F$5:F1000) -> 417 | D38: =SUMIF(Sale!H:H,B38,Sale!I:I) -> 0 | E38: =C38-D38 -> 417 | F38: =VLOOKUP(B38,Table1[[Variety]:[Column1]],5,FALSE) -> 5500 | G38: =C38*0.4 -> 166.8 | H38: =D38*0.4 -> 0 | I38: =E38*0.4 -> 166.8 | K38: =IF(right(B38,2)="KG","TL","VS") -> VS
B39: HI-8759(पूसा तेजस) MAR-25-12-763-52 (FII) | C39: =sumif(Purchase!E$5:E1000,B39,Purchase!F$5:F1000) -> 435 | D39: =SUMIF(Sale!H:H,B39,Sale!I:I) -> 0 | E39: =C39-D39 -> 435 | F39: =VLOOKUP(B39,Table1[[Variety]:[Column1]],5,FALSE) -> 5500 | G39: =C39*0.4 -> 174 | H39: =D39*0.4 -> 0 | I39: =E39*0.4 -> 174 | K39: =IF(right(B39,2)="KG","TL","VS") -> VS
B40: HI-8759(पूसा तेजस) MAR-25-12-763-51 (FII) | C40: =sumif(Purchase!E$5:E1000,B40,Purchase!F$5:F1000) -> 441 | D40: =SUMIF(Sale!H:H,B40,Sale!I:I) -> 0 | E40: =C40-D40 -> 441 | F40: =VLOOKUP(B40,Table1[[Variety]:[Column1]],5,FALSE) -> 5500 | G40: =C40*0.4 -> 176.4 | H40: =D40*0.4 -> 0 | I40: =E40*0.4 -> 176.4 | K40: =IF(right(B40,2)="KG","TL","VS") -> VS
B41: HI-8759(पूसा तेजस) MAR-25-12-763-52(2) (FII) | C41: =sumif(Purchase!E$5:E1000,B41,Purchase!F$5:F1000) -> 618 | D41: =SUMIF(Sale!H:H,B41,Sale!I:I) -> 0 | E41: =C41-D41 -> 618 | F41: =VLOOKUP(B41,Table1[[Variety]:[Column1]],5,FALSE) -> 5500 | G41: =C41*0.4 -> 247.2 | H41: =D41*0.4 -> 0 | I41: =E41*0.4 -> 247.2 | K41: =IF(right(B41,2)="KG","TL","VS") -> VS
...

Sheet temp
A1: Invoice no | B1: Customer name | C1: Village | D1: Mobile No | E1: item1 | F1: bag1 | G1: quantity1 | H1: rate1 | I1: amount1 | J1: item2 | K1: bag2 | L1: quantity2 | M1: rate2 | N1: amount2 | O1: item3 | P1: bag3 | Q1: quantity3 | R1: rate3 | S1: amount3 | T1: item4 | U1: bag4 | V1: quantity4 | W1: rate4 | X1: amount4 | Y1: item5 | Z1: bag5 | AA1: quantity5 | AB1: rate5 | AC1: amount5 | AD1: Date | AE1: Grand Total | AF1: packing
A2: 8846 | E2: GW-513 40KG | F2: 5 | G2: 2 | H2: 5300 | I2: 10600 | J2: HI-1655(पूसा हर्षा) 40KG | K2: 10 | L2: 4 | M2: 5300 | N2: 21200 | O2: JKG 5 KABULI 50KG | Q2: 0 | R2: 12000 | S2: 0 | V2: 0 | X2: 0 | AA2: 0 | AC2: 0 | AD2: {=Sale!V52} | AE2: =SUM(AC2, X2,S2,N2,I2) -> 31800 | AF2: 40
A3: 3597 | B3: sarang | C3: huh | D3: 21212 | E3: HI-8663 (पोषण ) APR-2024-12-763-135628-FI-B | F3: 4 | G3: 1.6 | H3: 5000 | I3: 8000 | J3: GW-513 APR-2024-12-763-135624-FII-(I)-A | K3: 3 | L3: 1.2 | M3: 5000 | N3: 6000 | Q3: 0 | S3: 0 | V3: 0 | X3: 0 | AA3: 0 | AC3: 0 | AD3: {=Sale!V52} | AE3: =SUM(AC3, X3,S3,N3,I3) -> 14000 | AF3: 40

Sheet Document Studio Logs
A1: 45919.731 | B1: Document Studio Logs | C1: 👋🏻 Please do not edit or delete this sheet)
A2: 45919.78 | B2: ✔️ Task #ouolne - Create PDF file from Sales quote | C2: {"exportFileName":"invoice","parentFolderName":"KaiZen","viewersCanCopy":true,"templateId":"1uaZo4R9aDdjSU591lPAJWjib2cPowIjAvw0Hf9DDA4g","exportMime":"application/pdf","parentFolderId":"18B9k736nxq1PXeSY7UPUBtkI0h2zg6y3","templateMime":"application/vnd.google-apps.document","sendNotifications":true,"templateName":"Sales quote"}
A3: 45919.78 | B3: ✔️ Workflow #pc5gsn - Vasundhara | C3: {"timeDelay":false,"triggerHourly":false,"sheetId":"638907871","formId":"","owner":"ninad.abhyankar88@gmail.com","triggerFormSubmit":false,"timeZone":"Asia/Calcutta","ssId":"1VFgwklCy6FlEVCuXBgnWfpL2l5rvg3gNTMn5j1RThWU","skipHidden":true} | D3: [[{"field":"{{Processed}}","value":"1","compare":"NOT_EQUAL_TO"}]]
A4: 45919.773 | B4: ✔️ Task #gzpzae - Create PDF file from Sales quote | C4: {"templateMime":"application/vnd.google-apps.document","parentFolderName":"KaiZen","templateId":"1uaZo4R9aDdjSU591lPAJWjib2cPowIjAvw0Hf9DDA4g","viewersCanCopy":true,"templateName":"Sales quote","exportFileName":"Invoice","parentFolderId":"18B9k736nxq1PXeSY7UPUBtkI0h2zg6y3","exportMime":"application/pdf","sendNotifications":true}
A5: 45919.773 | B5: ✔️ Workflow #brcrx3 - Vasundhara | C5: {"owner":"ninad.abhyankar88@gmail.com","ssId":"1VFgwklCy6FlEVCuXBgnWfpL2l5rvg3gNTMn5j1RThWU","timeZone":"Asia/Calcutta","timeDelay":false,"triggerFormSubmit":false,"sheetId":"638907871","formId":"","skipHidden":true,"triggerHourly":false} | D5: [[{"field":"{{Processed}}","value":"1","compare":"NOT_EQUAL_TO"}]]
A6: 45919.769 | B6: ✔️ Task #gzpzae - Create PDF file from Sales quote | C6: {"templateMime":"application/vnd.google-apps.document","exportFileName":"Invoice","templateName":"Sales quote","viewersCanCopy":true,"sendNotifications":true,"exportMime":"application/pdf","parentFolderId":"18B9k736nxq1PXeSY7UPUBtkI0h2zg6y3","parentFolderName":"KaiZen","templateId":"1uaZo4R9aDdjSU591lPAJWjib2cPowIjAvw0Hf9DDA4g"}
A7: 45919.769 | B7: ✔️ Workflow #brcrx3 - Vasundhara | C7: {"sheetId":"638907871","formId":"","timeDelay":false,"owner":"ninad.abhyankar88@gmail.com","triggerFormSubmit":false,"triggerHourly":false,"timeZone":"Asia/Calcutta","ssId":"1VFgwklCy6FlEVCuXBgnWfpL2l5rvg3gNTMn5j1RThWU","skipHidden":true} | D7: [[{"compare":"NOT_CONTAINS","value":"yes","field":"{{Processed}}"}]]
A8: 45919.741 | B8: ✔️ Task #gzpzae - Create PDF file from Sales quote | C8: {"parentFolderId":"18B9k736nxq1PXeSY7UPUBtkI0h2zg6y3","parentFolderName":"KaiZen","templateName":"Sales quote","templateId":"1uaZo4R9aDdjSU591lPAJWjib2cPowIjAvw0Hf9DDA4g","viewersCanCopy":true,"templateMime":"application/vnd.google-apps.document","sendNotifications":true,"exportFileName":"Invoice","exportMime":"application/pdf"}
A9: 45919.741 | B9: ✔️ Workflow #brcrx3 - Vasundhara | C9: {"formId":"","timeZone":"Asia/Calcutta","triggerFormSubmit":false,"sheetId":"638907871","triggerHourly":false,"timeDelay":false,"ssId":"1VFgwklCy6FlEVCuXBgnWfpL2l5rvg3gNTMn5j1RThWU","skipHidden":true,"owner":"ninad.abhyankar88@gmail.com"}
A10: 45919.736 | B10: ✔️ Processed 1 rows in 19 seconds | C10: 2
A11: 45919.731 | B11: ✔️ Task #gzpzae - Create PDF file from Sales quote | C11: {"exportFileName":"Invoice","templateMime":"application/vnd.google-apps.document","parentFolderName":"KaiZen","templateId":"1uaZo4R9aDdjSU591lPAJWjib2cPowIjAvw0Hf9DDA4g","templateName":"Sales quote","viewersCanCopy":true,"sendNotifications":true,"exportMime":"application/pdf","parentFolderId":"18B9k736nxq1PXeSY7UPUBtkI0h2zg6y3"}
A12: 45919.731 | B12: ✔️ Workflow #brcrx3 - Vasundhara | C12: {"timeDelay":false,"formId":"","triggerHourly":false,"skipHidden":true,"sheetId":"638907871","timeZone":"Asia/Calcutta","ssId":"1VFgwklCy6FlEVCuXBgnWfpL2l5rvg3gNTMn5j1RThWU","owner":"ninad.abhyankar88@gmail.com","triggerFormSubmit":false}
